Workbook

Sheet customer_churn_dataset
A1: customer_id | B1: plan_type | C1: contract_type | D1: monthly_charge | E1: tenure_months | F1: signup_date | G1: payment_method | H1: autopay_enabled | I1: usage_score | J1: logins_per_month | K1: features_used | L1: support_tickets_6m | M1: complaint_unresolved | N1: total_revenue | O1: churned | P1: churn_date | Q1: last_active_date | R1: signup_year | S1: Tenure_budget | T1: Risk_score | U1: Missing_value_flag | V1: Risk_level
A2: CUST100500 | B2: Standard | C2: Month-to-month | D2: 21.31 | E2: 20 | F2: 43833 | G2: Credit card | H2: 1 | I2: 78.8 | J2: 8 | K2: 8 | L2: 2 | M2: 1 | N2: 426.2 | O2: 0 | Q2: 44441 | R2: =IF(ISBLANK(F2),"Missing",IFERROR(YEAR(F2),"Missing")) -> 2020 | S2: =IF(ISBLANK(E2),"Missing",IF(E2<6,"0-6mo",IF(E2<12,"6-12mo",IF(E2<24,"12-24mo","24mo+")))) -> 12-24mo | T2: =IF(ISBLANK(C2),0,IF(C2="Month-to-month",2,IF(C2="One year",1,0)))+IF(ISBLANK(I2),0,IF(I2<40,2,IF(I2<55,1,0)))+IF(ISBLANK(M2),0,IF(M2=1,3,0))+IF(ISBLANK(L2),0,IF(L2>=2,1,0))+IF(ISBLANK(E2),0,IF(E2<12,1,0)) -> 6 | U2: =IF((ISBLANK(B2)*1+ISBLANK(C2)*1+ISBLANK(D2)*1+ISBLANK(E2)*1+ISBLANK(F2)*1+ISBLANK(I2)*1+ISBLANK(J2)*1+ISBLANK(K2)*1+ISBLANK(L2)*1+ISBLANK(M2)*1+ISBLANK(N2)*1+ISBLANK(O2)*1)>0,"Missing Data","OK") -> OK | V2: =IF(T2>=6,"High Risk",IF(T2>=3,"Medium Risk","Low Risk")) -> High Risk
A3: CUST101041 | B3: Standard | C3: Month-to-month | D3: 19.8 | E3: 33 | F3: 43833 | G3: Manual/Invoice | H3: 1 | I3: 46.1 | J3: 20 | K3: 4 | L3: 0 | M3: 0 | N3: 653.4 | O3: 0 | Q3: 44837 | R3: =IF(ISBLANK(F3),"Missing",IFERROR(YEAR(F3),"Missing")) -> 2020 | S3: =IF(ISBLANK(E3),"Missing",IF(E3<6,"0-6mo",IF(E3<12,"6-12mo",IF(E3<24,"12-24mo","24mo+")))) -> 24mo+ | T3: =IF(ISBLANK(C3),0,IF(C3="Month-to-month",2,IF(C3="One year",1,0)))+IF(ISBLANK(I3),0,IF(I3<40,2,IF(I3<55,1,0)))+IF(ISBLANK(M3),0,IF(M3=1,3,0))+IF(ISBLANK(L3),0,IF(L3>=2,1,0))+IF(ISBLANK(E3),0,IF(E3<12,1,0)) -> 3 | U3: =IF((ISBLANK(B3)*1+ISBLANK(C3)*1+ISBLANK(D3)*1+ISBLANK(E3)*1+ISBLANK(F3)*1+ISBLANK(I3)*1+ISBLANK(J3)*1+ISBLANK(K3)*1+ISBLANK(L3)*1+ISBLANK(M3)*1+ISBLANK(N3)*1+ISBLANK(O3)*1)>0,"Missing Data","OK") -> OK | V3: =IF(T3>=6,"High Risk",IF(T3>=3,"Medium Risk","Low Risk")) -> Medium Risk
A4: CUST100305 | B4: Premium | C4: Month-to-month | D4: 40.58 | E4: 18 | F4: 43834 | G4: Bank transfer | H4: 1 | I4: 49.8 | J4: 17 | K4: 6 | L4: 3 | M4: 0 | N4: 730.44 | O4: 0 | Q4: 44381 | R4: =IF(ISBLANK(F4),"Missing",IFERROR(YEAR(F4),"Missing")) -> 2020 | S4: =IF(ISBLANK(E4),"Missing",IF(E4<6,"0-6mo",IF(E4<12,"6-12mo",IF(E4<24,"12-24mo","24mo+")))) -> 12-24mo | T4: =IF(ISBLANK(C4),0,IF(C4="Month-to-month",2,IF(C4="One year",1,0)))+IF(ISBLANK(I4),0,IF(I4<40,2,IF(I4<55,1,0)))+IF(ISBLANK(M4),0,IF(M4=1,3,0))+IF(ISBLANK(L4),0,IF(L4>=2,1,0))+IF(ISBLANK(E4),0,IF(E4<12,1,0)) -> 4 | U4: =IF((ISBLANK(B4)*1+ISBLANK(C4)*1+ISBLANK(D4)*1+ISBLANK(E4)*1+ISBLANK(F4)*1+ISBLANK(I4)*1+ISBLANK(J4)*1+ISBLANK(K4)*1+ISBLANK(L4)*1+ISBLANK(M4)*1+ISBLANK(N4)*1+ISBLANK(O4)*1)>0,"Missing Data","OK") -> OK | V4: =IF(T4>=6,"High Risk",IF(T4>=3,"Medium Risk","Low Risk")) -> Medium Risk
A5: CUST101045 | B5: Standard | C5: Month-to-month | D5: 20.46 | E5: 57 | F5: 43837 | G5: Credit card | H5: 0 | I5: 42.4 | J5: 10 | K5: 3 | L5: 1 | M5: 0 | N5: 1166.22 | O5: 0 | Q5: 45572 | R5: =IF(ISBLANK(F5),"Missing",IFERROR(YEAR(F5),"Missing")) -> 2020 | S5: =IF(ISBLANK(E5),"Missing",IF(E5<6,"0-6mo",IF(E5<12,"6-12mo",IF(E5<24,"12-24mo","24mo+")))) -> 24mo+ | T5: =IF(ISBLANK(C5),0,IF(C5="Month-to-month",2,IF(C5="One year",1,0)))+IF(ISBLANK(I5),0,IF(I5<40,2,IF(I5<55,1,0)))+IF(ISBLANK(M5),0,IF(M5=1,3,0))+IF(ISBLANK(L5),0,IF(L5>=2,1,0))+IF(ISBLANK(E5),0,IF(E5<12,1,0)) -> 3 | U5: =IF((ISBLANK(B5)*1+ISBLANK(C5)*1+ISBLANK(D5)*1+ISBLANK(E5)*1+ISBLANK(F5)*1+ISBLANK(I5)*1+ISBLANK(J5)*1+ISBLANK(K5)*1+ISBLANK(L5)*1+ISBLANK(M5)*1+ISBLANK(N5)*1+ISBLANK(O5)*1)>0,"Missing Data","OK") -> OK | V5: =IF(T5>=6,"High Risk",IF(T5>=3,"Medium Risk","Low Risk")) -> Medium Risk
A6: CUST101341 | B6: Standard | C6: Month-to-month | D6: 20.96 | E6: 9 | F6: 43837 | G6: Bank transfer | H6: 1 | I6: 54.2 | J6: 17 | K6: 6 | L6: 2 | M6: 1 | N6: 188.64 | O6: 0 | Q6: 44110 | R6: =IF(ISBLANK(F6),"Missing",IFERROR(YEAR(F6),"Missing")) -> 2020 | S6: =IF(ISBLANK(E6),"Missing",IF(E6<6,"0-6mo",IF(E6<12,"6-12mo",IF(E6<24,"12-24mo","24mo+")))) -> 6-12mo | T6: =IF(ISBLANK(C6),0,IF(C6="Month-to-month",2,IF(C6="One year",1,0)))+IF(ISBLANK(I6),0,IF(I6<40,2,IF(I6<55,1,0)))+IF(ISBLANK(M6),0,IF(M6=1,3,0))+IF(ISBLANK(L6),0,IF(L6>=2,1,0))+IF(ISBLANK(E6),0,IF(E6<12,1,0)) -> 8 | U6: =IF((ISBLANK(B6)*1+ISBLANK(C6)*1+ISBLANK(D6)*1+ISBLANK(E6)*1+ISBLANK(F6)*1+ISBLANK(I6)*1+ISBLANK(J6)*1+ISBLANK(K6)*1+ISBLANK(L6)*1+ISBLANK(M6)*1+ISBLANK(N6)*1+ISBLANK(O6)*1)>0,"Missing Data","OK") -> OK | V6: =IF(T6>=6,"High Risk",IF(T6>=3,"Medium Risk","Low Risk")) -> High Risk
A7: CUST101313 | B7: Premium | C7: One year | D7: 38.61 | E7: 8 | F7: 43839 | G7: Credit card | H7: 0 | I7: 45.7 | J7: 14 | K7: 2 | L7: 1 | M7: 1 | N7: 308.88 | O7: 1 | P7: 44082 | Q7: 44082 | R7: =IF(ISBLANK(F7),"Missing",IFERROR(YEAR(F7),"Missing")) -> 2020 | S7: =IF(ISBLANK(E7),"Missing",IF(E7<6,"0-6mo",IF(E7<12,"6-12mo",IF(E7<24,"12-24mo","24mo+")))) -> 6-12mo | T7: =IF(ISBLANK(C7),0,IF(C7="Month-to-month",2,IF(C7="One year",1,0)))+IF(ISBLANK(I7),0,IF(I7<40,2,IF(I7<55,1,0)))+IF(ISBLANK(M7),0,IF(M7=1,3,0))+IF(ISBLANK(L7),0,IF(L7>=2,1,0))+IF(ISBLANK(E7),0,IF(E7<12,1,0)) -> 6 | U7: =IF((ISBLANK(B7)*1+ISBLANK(C7)*1+ISBLANK(D7)*1+ISBLANK(E7)*1+ISBLANK(F7)*1+ISBLANK(I7)*1+ISBLANK(J7)*1+ISBLANK(K7)*1+ISBLANK(L7)*1+ISBLANK(M7)*1+ISBLANK(N7)*1+ISBLANK(O7)*1)>0,"Missing Data","OK") -> OK | V7: =IF(T7>=6,"High Risk",IF(T7>=3,"Medium Risk","Low Risk")) -> High Risk
A8: CUST100592 | B8: Basic | C8: Month-to-month | D8: 9.34 | E8: 72 | F8: 43842 | G8: Bank transfer | H8: 0 | I8: 72.8 | J8: 25 | K8: 8 | L8: 1 | M8: 0 | N8: 672.48 | O8: 0 | Q8: 46033 | R8: =IF(ISBLANK(F8),"Missing",IFERROR(YEAR(F8),"Missing")) -> 2020 | S8: =IF(ISBLANK(E8),"Missing",IF(E8<6,"0-6mo",IF(E8<12,"6-12mo",IF(E8<24,"12-24mo","24mo+")))) -> 24mo+ | T8: =IF(ISBLANK(C8),0,IF(C8="Month-to-month",2,IF(C8="One year",1,0)))+IF(ISBLANK(I8),0,IF(I8<40,2,IF(I8<55,1,0)))+IF(ISBLANK(M8),0,IF(M8=1,3,0))+IF(ISBLANK(L8),0,IF(L8>=2,1,0))+IF(ISBLANK(E8),0,IF(E8<12,1,0)) -> 2 | U8: =IF((ISBLANK(B8)*1+ISBLANK(C8)*1+ISBLANK(D8)*1+ISBLANK(E8)*1+ISBLANK(F8)*1+ISBLANK(I8)*1+ISBLANK(J8)*1+ISBLANK(K8)*1+ISBLANK(L8)*1+ISBLANK(M8)*1+ISBLANK(N8)*1+ISBLANK(O8)*1)>0,"Missing Data","OK") -> OK | V8: =IF(T8>=6,"High Risk",IF(T8>=3,"Medium Risk","Low Risk")) -> Low Risk
A9: CUST101076 | B9: Basic | C9: Month-to-month | D9: 10 | E9: 0 | F9: 43843 | G9: Credit card | H9: 0 | I9: 33.9 | J9: 9 | K9: 4 | L9: 1 | M9: 0 | N9: 0 | O9: 1 | P9: 43843 | Q9: 43843 | R9: =IF(ISBLANK(F9),"Missing",IFERROR(YEAR(F9),"Missing")) -> 2020 | S9: =IF(ISBLANK(E9),"Missing",IF(E9<6,"0-6mo",IF(E9<12,"6-12mo",IF(E9<24,"12-24mo","24mo+")))) -> 0-6mo | T9: =IF(ISBLANK(C9),0,IF(C9="Month-to-month",2,IF(C9="One year",1,0)))+IF(ISBLANK(I9),0,IF(I9<40,2,IF(I9<55,1,0)))+IF(ISBLANK(M9),0,IF(M9=1,3,0))+IF(ISBLANK(L9),0,IF(L9>=2,1,0))+IF(ISBLANK(E9),0,IF(E9<12,1,0)) -> 5 | U9: =IF((ISBLANK(B9)*1+ISBLANK(C9)*1+ISBLANK(D9)*1+ISBLANK(E9)*1+ISBLANK(F9)*1+ISBLANK(I9)*1+ISBLANK(J9)*1+ISBLANK(K9)*1+ISBLANK(L9)*1+ISBLANK(M9)*1+ISBLANK(N9)*1+ISBLANK(O9)*1)>0,"Missing Data","OK") -> OK | V9: =IF(T9>=6,"High Risk",IF(T9>=3,"Medium Risk","Low Risk")) -> Medium Risk
A10: CUST101481 | B10: Basic | C10: Month-to-month | D10: 9.77 | E10: 72 | F10: 43843 | G10: PayPal | H10: 0 | I10: 38.9 | J10: 10 | K10: 4 | L10: 1 | M10: 1 | N10: 703.44 | O10: 0 | Q10: 46034 | R10: =IF(ISBLANK(F10),"Missing",IFERROR(YEAR(F10),"Missing")) -> 2020 | S10: =IF(ISBLANK(E10),"Missing",IF(E10<6,"0-6mo",IF(E10<12,"6-12mo",IF(E10<24,"12-24mo","24mo+")))) -> 24mo+ | T10: =IF(ISBLANK(C10),0,IF(C10="Month-to-month",2,IF(C10="One year",1,0)))+IF(ISBLANK(I10),0,IF(I10<40,2,IF(I10<55,1,0)))+IF(ISBLANK(M10),0,IF(M10=1,3,0))+IF(ISBLANK(L10),0,IF(L10>=2,1,0))+IF(ISBLANK(E10),0,IF(E10<12,1,0)) -> 7 | U10: =IF((ISBLANK(B10)*1+ISBLANK(C10)*1+ISBLANK(D10)*1+ISBLANK(E10)*1+ISBLANK(F10)*1+ISBLANK(I10)*1+ISBLANK(J10)*1+ISBLANK(K10)*1+ISBLANK(L10)*1+ISBLANK(M10)*1+ISBLANK(N10)*1+ISBLANK(O10)*1)>0,"Missing Data","OK") -> OK | V10: =IF(T10>=6,"High Risk",IF(T10>=3,"Medium Risk","Low Risk")) -> High Risk
A11: CUST100688 | B11: Standard | C11: One year | D11: 20.96 | E11: 39 | F11: 43845 | G11: PayPal | H11: 1 | I11: 42.3 | J11: 10 | K11: 5 | L11: 1 | M11: 1 | N11: 817.44 | O11: 0 | Q11: 45032 | R11: =IF(ISBLANK(F11),"Missing",IFERROR(YEAR(F11),"Missing")) -> 2020 | S11: =IF(ISBLANK(E11),"Missing",IF(E11<6,"0-6mo",IF(E11<12,"6-12mo",IF(E11<24,"12-24mo","24mo+")))) -> 24mo+ | T11: =IF(ISBLANK(C11),0,IF(C11="Month-to-month",2,IF(C11="One year",1,0)))+IF(ISBLANK(I11),0,IF(I11<40,2,IF(I11<55,1,0)))+IF(ISBLANK(M11),0,IF(M11=1,3,0))+IF(ISBLANK(L11),0,IF(L11>=2,1,0))+IF(ISBLANK(E11),0,IF(E11<12,1,0)) -> 5 | U11: =IF((ISBLANK(B11)*1+ISBLANK(C11)*1+ISBLANK(D11)*1+ISBLANK(E11)*1+ISBLANK(F11)*1+ISBLANK(I11)*1+ISBLANK(J11)*1+ISBLANK(K11)*1+ISBLANK(L11)*1+ISBLANK(M11)*1+ISBLANK(N11)*1+ISBLANK(O11)*1)>0,"Missing Data","OK") -> OK | V11: =IF(T11>=6,"High Risk",IF(T11>=3,"Medium Risk","Low Risk")) -> Medium Risk
A12: CUST100968 | B12: Standard | C12: Month-to-month | D12: 20.71 | E12: 35 | F12: 43845 | G12: Credit card | H12: 0 | I12: 76.7 | J12: 25 | K12: 6 | L12: 0 | M12: 0 | N12: 724.85 | O12: 0 | Q12: 44910 | R12: =IF(ISBLANK(F12),"Missing",IFERROR(YEAR(F12),"Missing")) -> 2020 | S12: =IF(ISBLANK(E12),"Missing",IF(E12<6,"0-6mo",IF(E12<12,"6-12mo",IF(E12<24,"12-24mo","24mo+")))) -> 24mo+ | T12: =IF(ISBLANK(C12),0,IF(C12="Month-to-month",2,IF(C12="One year",1,0)))+IF(ISBLANK(I12),0,IF(I12<40,2,IF(I12<55,1,0)))+IF(ISBLANK(M12),0,IF(M12=1,3,0))+IF(ISBLANK(L12),0,IF(L12>=2,1,0))+IF(ISBLANK(E12),0,IF(E12<12,1,0)) -> 2 | U12: =IF((ISBLANK(B12)*1+ISBLANK(C12)*1+ISBLANK(D12)*1+ISBLANK(E12)*1+ISBLANK(F12)*1+ISBLANK(I12)*1+ISBLANK(J12)*1+ISBLANK(K12)*1+ISBLANK(L12)*1+ISBLANK(M12)*1+ISBLANK(N12)*1+ISBLANK(O12)*1)>0,"Missing Data","OK") -> OK | V12: =IF(T12>=6,"High Risk",IF(T12>=3,"Medium Risk","Low Risk")) -> Low Risk
A13: CUST101408 | B13: Standard | C13: Month-to-month | D13: 20.85 | E13: 19 | F13: 43845 | G13: Credit card | H13: 1 | I13: 47.5 | J13: 20 | K13: 6 | L13: 3 | M13: 0 | N13: 396.15 | O13: 0 | Q13: 44423 | R13: =IF(ISBLANK(F13),"Missing",IFERROR(YEAR(F13),"Missing")) -> 2020 | S13: =IF(ISBLANK(E13),"Missing",IF(E13<6,"0-6mo",IF(E13<12,"6-12mo",IF(E13<24,"12-24mo","24mo+")))) -> 12-24mo | T13: =IF(ISBLANK(C13),0,IF(C13="Month-to-month",2,IF(C13="One year",1,0)))+IF(ISBLANK(I13),0,IF(I13<40,2,IF(I13<55,1,0)))+IF(ISBLANK(M13),0,IF(M13=1,3,0))+IF(ISBLANK(L13),0,IF(L13>=2,1,0))+IF(ISBLANK(E13),0,IF(E13<12,1,0)) -> 4 | U13: =IF((ISBLANK(B13)*1+ISBLANK(C13)*1+ISBLANK(D13)*1+ISBLANK(E13)*1+ISBLANK(F13)*1+ISBLANK(I13)*1+ISBLANK(J13)*1+ISBLANK(K13)*1+ISBLANK(L13)*1+ISBLANK(M13)*1+ISBLANK(N13)*1+ISBLANK(O13)*1)>0,"Missing Data","OK") -> OK | V13: =IF(T13>=6,"High Risk",IF(T13>=3,"Medium Risk","Low Risk")) -> Medium Risk
A14: CUST101084 | B14: Premium | C14: Month-to-month | D14: 41.61 | E14: 3 | F14: 43847 | G14: PayPal | H14: 1 | I14: 80 | J14: 19 | K14: 8 | L14: 2 | M14: 1 | N14: 124.83 | O14: 1 | P14: 43938 | Q14: 43938 | R14: =IF(ISBLANK(F14),"Missing",IFERROR(YEAR(F14),"Missing")) -> 2020 | S14: =IF(ISBLANK(E14),"Missing",IF(E14<6,"0-6mo",IF(E14<12,"6-12mo",IF(E14<24,"12-24mo","24mo+")))) -> 0-6mo | T14: =IF(ISBLANK(C14),0,IF(C14="Month-to-month",2,IF(C14="One year",1,0)))+IF(ISBLANK(I14),0,IF(I14<40,2,IF(I14<55,1,0)))+IF(ISBLANK(M14),0,IF(M14=1,3,0))+IF(ISBLANK(L14),0,IF(L14>=2,1,0))+IF(ISBLANK(E14),0,IF(E14<12,1,0)) -> 7 | U14: =IF((ISBLANK(B14)*1+ISBLANK(C14)*1+ISBLANK(D14)*1+ISBLANK(E14)*1+ISBLANK(F14)*1+ISBLANK(I14)*1+ISBLANK(J14)*1+ISBLANK(K14)*1+ISBLANK(L14)*1+ISBLANK(M14)*1+ISBLANK(N14)*1+ISBLANK(O14)*1)>0,"Missing Data","OK") -> OK | V14: =IF(T14>=6,"High Risk",IF(T14>=3,"Medium Risk","Low Risk")) -> High Risk
A15: CUST101306 | B15: Standard | C15: One year | D15: 19.23 | E15: 1 | F15: 43850 | G15: Bank transfer | H15: 1 | I15: 59.1 | J15: 17 | K15: 5 | L15: 1 | M15: 0 | N15: 19.23 | O15: 0 | Q15: 43880 | R15: =IF(ISBLANK(F15),"Missing",IFERROR(YEAR(F15),"Missing")) -> 2020 | S15: =IF(ISBLANK(E15),"Missing",IF(E15<6,"0-6mo",IF(E15<12,"6-12mo",IF(E15<24,"12-24mo","24mo+")))) -> 0-6mo | T15: =IF(ISBLANK(C15),0,IF(C15="Month-to-month",2,IF(C15="One year",1,0)))+IF(ISBLANK(I15),0,IF(I15<40,2,IF(I15<55,1,0)))+IF(ISBLANK(M15),0,IF(M15=1,3,0))+IF(ISBLANK(L15),0,IF(L15>=2,1,0))+IF(ISBLANK(E15),0,IF(E15<12,1,0)) -> 2 | U15: =IF((ISBLANK(B15)*1+ISBLANK(C15)*1+ISBLANK(D15)*1+ISBLANK(E15)*1+ISBLANK(F15)*1+ISBLANK(I15)*1+ISBLANK(J15)*1+ISBLANK(K15)*1+ISBLANK(L15)*1+ISBLANK(M15)*1+ISBLANK(N15)*1+ISBLANK(O15)*1)>0,"Missing Data","OK") -> OK | V15: =IF(T15>=6,"High Risk",IF(T15>=3,"Medium Risk","Low Risk")) -> Low Risk
A16: CUST100916 | B16: Basic | C16: Month-to-month | D16: 10.61 | E16: 19 | F16: 43850 | G16: Credit card | H16: 1 | I16: 90.1 | J16: 21 | K16: 10 | L16: 0 | M16: 0 | N16: 201.59 | O16: 0 | Q16: 44428 | R16: =IF(ISBLANK(F16),"Missing",IFERROR(YEAR(F16),"Missing")) -> 2020 | S16: =IF(ISBLANK(E16),"Missing",IF(E16<6,"0-6mo",IF(E16<12,"6-12mo",IF(E16<24,"12-24mo","24mo+")))) -> 12-24mo | T16: =IF(ISBLANK(C16),0,IF(C16="Month-to-month",2,IF(C16="One year",1,0)))+IF(ISBLANK(I16),0,IF(I16<40,2,IF(I16<55,1,0)))+IF(ISBLANK(M16),0,IF(M16=1,3,0))+IF(ISBLANK(L16),0,IF(L16>=2,1,0))+IF(ISBLANK(E16),0,IF(E16<12,1,0)) -> 2 | U16: =IF((ISBLANK(B16)*1+ISBLANK(C16)*1+ISBLANK(D16)*1+ISBLANK(E16)*1+ISBLANK(F16)*1+ISBLANK(I16)*1+ISBLANK(J16)*1+ISBLANK(K16)*1+ISBLANK(L16)*1+ISBLANK(M16)*1+ISBLANK(N16)*1+ISBLANK(O16)*1)>0,"Missing Data","OK") -> OK | V16: =IF(T16>=6,"High Risk",IF(T16>=3,"Medium Risk","Low Risk")) -> Low Risk
A17: CUST100655 | B17: Basic | C17: Month-to-month | D17: 9.1 | E17: 18 | F17: 43850 | G17: Bank transfer | H17: 0 | I17: 88.9 | J17: 30 | K17: 10 | L17: 0 | M17: 0 | N17: 163.8 | O17: 1 | P17: 44397 | Q17: 44397 | R17: =IF(ISBLANK(F17),"Missing",IFERROR(YEAR(F17),"Missing")) -> 2020 | S17: =IF(ISBLANK(E17),"Missing",IF(E17<6,"0-6mo",IF(E17<12,"6-12mo",IF(E17<24,"12-24mo","24mo+")))) -> 12-24mo | T17: =IF(ISBLANK(C17),0,IF(C17="Month-to-month",2,IF(C17="One year",1,0)))+IF(ISBLANK(I17),0,IF(I17<40,2,IF(I17<55,1,0)))+IF(ISBLANK(M17),0,IF(M17=1,3,0))+IF(ISBLANK(L17),0,IF(L17>=2,1,0))+IF(ISBLANK(E17),0,IF(E17<12,1,0)) -> 2 | U17: =IF((ISBLANK(B17)*1+ISBLANK(C17)*1+ISBLANK(D17)*1+ISBLANK(E17)*1+ISBLANK(F17)*1+ISBLANK(I17)*1+ISBLANK(J17)*1+ISBLANK(K17)*1+ISBLANK(L17)*1+ISBLANK(M17)*1+ISBLANK(N17)*1+ISBLANK(O17)*1)>0,"Missing Data","OK") -> OK | V17: =IF(T17>=6,"High Risk",IF(T17>=3,"Medium Risk","Low Risk")) -> Low Risk
A18: CUST100826 | B18: Basic | C18: Month-to-month | D18: 10.72 | E18: 25 | F18: 43851 | G18: PayPal | H18: 1 | I18: 61.2 | J18: 17 | K18: 6 | L18: 0 | M18: 0 | N18: 268 | O18: 0 | Q18: 44612 | R18: =IF(ISBLANK(F18),"Missing",IFERROR(YEAR(F18),"Missing")) -> 2020 | S18: =IF(ISBLANK(E18),"Missing",IF(E18<6,"0-6mo",IF(E18<12,"6-12mo",IF(E18<24,"12-24mo","24mo+")))) -> 24mo+ | T18: =IF(ISBLANK(C18),0,IF(C18="Month-to-month",2,IF(C18="One year",1,0)))+IF(ISBLANK(I18),0,IF(I18<40,2,IF(I18<55,1,0)))+IF(ISBLANK(M18),0,IF(M18=1,3,0))+IF(ISBLANK(L18),0,IF(L18>=2,1,0))+IF(ISBLANK(E18),0,IF(E18<12,1,0)) -> 2 | U18: =IF((ISBLANK(B18)*1+ISBLANK(C18)*1+ISBLANK(D18)*1+ISBLANK(E18)*1+ISBLANK(F18)*1+ISBLANK(I18)*1+ISBLANK(J18)*1+ISBLANK(K18)*1+ISBLANK(L18)*1+ISBLANK(M18)*1+ISBLANK(N18)*1+ISBLANK(O18)*1)>0,"Missing Data","OK") -> OK | V18: =IF(T18>=6,"High Risk",IF(T18>=3,"Medium Risk","Low Risk")) -> Low Risk
A19: CUST100747 | B19: Standard | C19: Month-to-month | D19: 18.86 | E19: 6 | F19: 43853 | G19: Credit card | H19: 1 | I19: 73 | J19: 31 | K19: 6 | L19: 0 | M19: 0 | N19: 113.16 | O19: 0 | Q19: 44035 | R19: =IF(ISBLANK(F19),"Missing",IFERROR(YEAR(F19),"Missing")) -> 2020 | S19: =IF(ISBLANK(E19),"Missing",IF(E19<6,"0-6mo",IF(E19<12,"6-12mo",IF(E19<24,"12-24mo","24mo+")))) -> 6-12mo | T19: =IF(ISBLANK(C19),0,IF(C19="Month-to-month",2,IF(C19="One year",1,0)))+IF(ISBLANK(I19),0,IF(I19<40,2,IF(I19<55,1,0)))+IF(ISBLANK(M19),0,IF(M19=1,3,0))+IF(ISBLANK(L19),0,IF(L19>=2,1,0))+IF(ISBLANK(E19),0,IF(E19<12,1,0)) -> 3 | U19: =IF((ISBLANK(B19)*1+ISBLANK(C19)*1+ISBLANK(D19)*1+ISBLANK(E19)*1+ISBLANK(F19)*1+ISBLANK(I19)*1+ISBLANK(J19)*1+ISBLANK(K19)*1+ISBLANK(L19)*1+ISBLANK(M19)*1+ISBLANK(N19)*1+ISBLANK(O19)*1)>0,"Missing Data","OK") -> OK | V19: =IF(T19>=6,"High Risk",IF(T19>=3,"Medium Risk","Low Risk")) -> Medium Risk
A20: CUST101402 | B20: Basic | C20: One year | D20: 9.06 | E20: 7 | F20: 43853 | G20: Credit card | H20: 1 | I20: 64.7 | J20: 22 | K20: 5 | L20: 0 | M20: 0 | N20: 63.42 | O20: 0 | Q20: 44066 | R20: =IF(ISBLANK(F20),"Missing",IFERROR(YEAR(F20),"Missing")) -> 2020 | S20: =IF(ISBLANK(E20),"Missing",IF(E20<6,"0-6mo",IF(E20<12,"6-12mo",IF(E20<24,"12-24mo","24mo+")))) -> 6-12mo | T20: =IF(ISBLANK(C20),0,IF(C20="Month-to-month",2,IF(C20="One year",1,0)))+IF(ISBLANK(I20),0,IF(I20<40,2,IF(I20<55,1,0)))+IF(ISBLANK(M20),0,IF(M20=1,3,0))+IF(ISBLANK(L20),0,IF(L20>=2,1,0))+IF(ISBLANK(E20),0,IF(E20<12,1,0)) -> 2 | U20: =IF((ISBLANK(B20)*1+ISBLANK(C20)*1+ISBLANK(D20)*1+ISBLANK(E20)*1+ISBLANK(F20)*1+ISBLANK(I20)*1+ISBLANK(J20)*1+ISBLANK(K20)*1+ISBLANK(L20)*1+ISBLANK(M20)*1+ISBLANK(N20)*1+ISBLANK(O20)*1)>0,"Missing Data","OK") -> OK | V20: =IF(T20>=6,"High Risk",IF(T20>=3,"Medium Risk","Low Risk")) -> Low Risk
A21: CUST100575 | B21: Premium | C21: Two year | D21: 38.37 | E21: 5 | F21: 43861 | G21: Bank transfer | H21: 1 | I21: 71.4 | J21: 23 | K21: 10 | L21: 2 | M21: 0 | N21: 191.85 | O21: 0 | Q21: 44013 | R21: =IF(ISBLANK(F21),"Missing",IFERROR(YEAR(F21),"Missing")) -> 2020 | S21: =IF(ISBLANK(E21),"Missing",IF(E21<6,"0-6mo",IF(E21<12,"6-12mo",IF(E21<24,"12-24mo","24mo+")))) -> 0-6mo | T21: =IF(ISBLANK(C21),0,IF(C21="Month-to-month",2,IF(C21="One year",1,0)))+IF(ISBLANK(I21),0,IF(I21<40,2,IF(I21<55,1,0)))+IF(ISBLANK(M21),0,IF(M21=1,3,0))+IF(ISBLANK(L21),0,IF(L21>=2,1,0))+IF(ISBLANK(E21),0,IF(E21<12,1,0)) -> 2 | U21: =IF((ISBLANK(B21)*1+ISBLANK(C21)*1+ISBLANK(D21)*1+ISBLANK(E21)*1+ISBLANK(F21)*1+ISBLANK(I21)*1+ISBLANK(J21)*1+ISBLANK(K21)*1+ISBLANK(L21)*1+ISBLANK(M21)*1+ISBLANK(N21)*1+ISBLANK(O21)*1)>0,"Missing Data","OK") -> OK | V21: =IF(T21>=6,"High Risk",IF(T21>=3,"Medium Risk","Low Risk")) -> Low Risk
A22: CUST100057 | B22: Basic | C22: Month-to-month | D22: 10.27 | E22: 46 | F22: 43864 | G22: Credit card | H22: 1 | I22: 28.1 | J22: 18 | K22: 1 | L22: 3 | M22: 0 | N22: 472.42 | O22: 0 | Q22: 45264 | R22: =IF(ISBLANK(F22),"Missing",IFERROR(YEAR(F22),"Missing")) -> 2020 | S22: =IF(ISBLANK(E22),"Missing",IF(E22<6,"0-6mo",IF(E22<12,"6-12mo",IF(E22<24,"12-24mo","24mo+")))) -> 24mo+ | T22: =IF(ISBLANK(C22),0,IF(C22="Month-to-month",2,IF(C22="One year",1,0)))+IF(ISBLANK(I22),0,IF(I22<40,2,IF(I22<55,1,0)))+IF(ISBLANK(M22),0,IF(M22=1,3,0))+IF(ISBLANK(L22),0,IF(L22>=2,1,0))+IF(ISBLANK(E22),0,IF(E22<12,1,0)) -> 5 | U22: =IF((ISBLANK(B22)*1+ISBLANK(C22)*1+ISBLANK(D22)*1+ISBLANK(E22)*1+ISBLANK(F22)*1+ISBLANK(I22)*1+ISBLANK(J22)*1+ISBLANK(K22)*1+ISBLANK(L22)*1+ISBLANK(M22)*1+ISBLANK(N22)*1+ISBLANK(O22)*1)>0,"Missing Data","OK") -> OK | V22: =IF(T22>=6,"High Risk",IF(T22>=3,"Medium Risk","Low Risk")) -> Medium Risk
A23: CUST100209 | B23: Basic | C23: Month-to-month | D23: 9.11 | E23: 16 | F23: 43865 | G23: Bank transfer | H23: 1 | I23: 58.6 | J23: 21 | K23: 8 | L23: 2 | M23: 1 | N23: 145.76 | O23: 0 | Q23: 44352 | R23: =IF(ISBLANK(F23),"Missing",IFERROR(YEAR(F23),"Missing")) -> 2020 | S23: =IF(ISBLANK(E23),"Missing",IF(E23<6,"0-6mo",IF(E23<12,"6-12mo",IF(E23<24,"12-24mo","24mo+")))) -> 12-24mo | T23: =IF(ISBLANK(C23),0,IF(C23="Month-to-month",2,IF(C23="One year",1,0)))+IF(ISBLANK(I23),0,IF(I23<40,2,IF(I23<55,1,0)))+IF(ISBLANK(M23),0,IF(M23=1,3,0))+IF(ISBLANK(L23),0,IF(L23>=2,1,0))+IF(ISBLANK(E23),0,IF(E23<12,1,0)) -> 6 | U23: =IF((ISBLANK(B23)*1+ISBLANK(C23)*1+ISBLANK(D23)*1+ISBLANK(E23)*1+ISBLANK(F23)*1+ISBLANK(I23)*1+ISBLANK(J23)*1+ISBLANK(K23)*1+ISBLANK(L23)*1+ISBLANK(M23)*1+ISBLANK(N23)*1+ISBLANK(O23)*1)>0,"Missing Data","OK") -> OK | V23: =IF(T23>=6,"High Risk",IF(T23>=3,"Medium Risk","Low Risk")) -> High Risk
A24: CUST100912 | B24: Standard | C24: Month-to-month | D24: 20.08 | E24: 38 | F24: 43865 | G24: Bank transfer | H24: 1 | I24: 81.3 | J24: 25 | K24: 7 | L24: 1 | M24: 0 | N24: 763.04 | O24: 0 | Q24: 45021 | R24: =IF(ISBLANK(F24),"Missing",IFERROR(YEAR(F24),"Missing")) -> 2020 | S24: =IF(ISBLANK(E24),"Missing",IF(E24<6,"0-6mo",IF(E24<12,"6-12mo",IF(E24<24,"12-24mo","24mo+")))) -> 24mo+ | T24: =IF(ISBLANK(C24),0,IF(C24="Month-to-month",2,IF(C24="One year",1,0)))+IF(ISBLANK(I24),0,IF(I24<40,2,IF(I24<55,1,0)))+IF(ISBLANK(M24),0,IF(M24=1,3,0))+IF(ISBLANK(L24),0,IF(L24>=2,1,0))+IF(ISBLANK(E24),0,IF(E24<12,1,0)) -> 2 | U24: =IF((ISBLANK(B24)*1+ISBLANK(C24)*1+ISBLANK(D24)*1+ISBLANK(E24)*1+ISBLANK(F24)*1+ISBLANK(I24)*1+ISBLANK(J24)*1+ISBLANK(K24)*1+ISBLANK(L24)*1+ISBLANK(M24)*1+ISBLANK(N24)*1+ISBLANK(O24)*1)>0,"Missing Data","OK") -> OK | V24: =IF(T24>=6,"High Risk",IF(T24>=3,"Medium Risk","Low Risk")) -> Low Risk
A25: CUST101240 | B25: Premium | C25: One year | D25: 39.27 | E25: 14 | F25: 43866 | G25: Credit card | H25: 1 | I25: 90.3 | J25: 33 | K25: 9 | L25: 1 | M25: 0 | N25: 549.78 | O25: 0 | Q25: 44292 | R25: =IF(ISBLANK(F25),"Missing",IFERROR(YEAR(F25),"Missing")) -> 2020 | S25: =IF(ISBLANK(E25),"Missing",IF(E25<6,"0-6mo",IF(E25<12,"6-12mo",IF(E25<24,"12-24mo","24mo+")))) -> 12-24mo | T25: =IF(ISBLANK(C25),0,IF(C25="Month-to-month",2,IF(C25="One year",1,0)))+IF(ISBLANK(I25),0,IF(I25<40,2,IF(I25<55,1,0)))+IF(ISBLANK(M25),0,IF(M25=1,3,0))+IF(ISBLANK(L25),0,IF(L25>=2,1,0))+IF(ISBLANK(E25),0,IF(E25<12,1,0)) -> 1 | U25: =IF((ISBLANK(B25)*1+ISBLANK(C25)*1+ISBLANK(D25)*1+ISBLANK(E25)*1+ISBLANK(F25)*1+ISBLANK(I25)*1+ISBLANK(J25)*1+ISBLANK(K25)*1+ISBLANK(L25)*1+ISBLANK(M25)*1+ISBLANK(N25)*1+ISBLANK(O25)*1)>0,"Missing Data","OK") -> OK | V25: =IF(T25>=6,"High Risk",IF(T25>=3,"Medium Risk","Low Risk")) -> Low Risk
A26: CUST100324 | B26: Premium | C26: One year | D26: 40.21 | E26: 8 | F26: 43868 | G26: Bank transfer | H26: 0 | I26: 77.4 | J26: 11 | K26: 6 | L26: 0 | M26: 0 | N26: 321.68 | O26: 0 | Q26: 44111 | R26: =IF(ISBLANK(F26),"Missing",IFERROR(YEAR(F26),"Missing")) -> 2020 | S26: =IF(ISBLANK(E26),"Missing",IF(E26<6,"0-6mo",IF(E26<12,"6-12mo",IF(E26<24,"12-24mo","24mo+")))) -> 6-12mo | T26: =IF(ISBLANK(C26),0,IF(C26="Month-to-month",2,IF(C26="One year",1,0)))+IF(ISBLANK(I26),0,IF(I26<40,2,IF(I26<55,1,0)))+IF(ISBLANK(M26),0,IF(M26=1,3,0))+IF(ISBLANK(L26),0,IF(L26>=2,1,0))+IF(ISBLANK(E26),0,IF(E26<12,1,0)) -> 2 | U26: =IF((ISBLANK(B26)*1+ISBLANK(C26)*1+ISBLANK(D26)*1+ISBLANK(E26)*1+ISBLANK(F26)*1+ISBLANK(I26)*1+ISBLANK(J26)*1+ISBLANK(K26)*1+ISBLANK(L26)*1+ISBLANK(M26)*1+ISBLANK(N26)*1+ISBLANK(O26)*1)>0,"Missing Data","OK") -> OK | V26: =IF(T26>=6,"High Risk",IF(T26>=3,"Medium Risk","Low Risk")) -> Low Risk
A27: CUST100360 | B27: Basic | C27: Month-to-month | D27: 11.21 | E27: 19 | F27: 43871 | G27: Credit card | H27: 1 | I27: 48.9 | J27: 15 | K27: 4 | L27: 0 | M27: 0 | N27: 212.99 | O27: 0 | Q27: 44449 | R27: =IF(ISBLANK(F27),"Missing",IFERROR(YEAR(F27),"Missing")) -> 2020 | S27: =IF(ISBLANK(E27),"Missing",IF(E27<6,"0-6mo",IF(E27<12,"6-12mo",IF(E27<24,"12-24mo","24mo+")))) -> 12-24mo | T27: =IF(ISBLANK(C27),0,IF(C27="Month-to-month",2,IF(C27="One year",1,0)))+IF(ISBLANK(I27),0,IF(I27<40,2,IF(I27<55,1,0)))+IF(ISBLANK(M27),0,IF(M27=1,3,0))+IF(ISBLANK(L27),0,IF(L27>=2,1,0))+IF(ISBLANK(E27),0,IF(E27<12,1,0)) -> 3 | U27: =IF((ISBLANK(B27)*1+ISBLANK(C27)*1+ISBLANK(D27)*1+ISBLANK(E27)*1+ISBLANK(F27)*1+ISBLANK(I27)*1+ISBLANK(J27)*1+ISBLANK(K27)*1+ISBLANK(L27)*1+ISBLANK(M27)*1+ISBLANK(N27)*1+ISBLANK(O27)*1)>0,"Missing Data","OK") -> OK | V27: =IF(T27>=6,"High Risk",IF(T27>=3,"Medium Risk","Low Risk")) -> Medium Risk
A28: CUST100746 | B28: Basic | C28: Month-to-month | D28: 8.42 | E28: 37 | F28: 43872 | G28: Credit card | H28: 1 | I28: 18.2 | J28: 8 | K28: 0 | L28: 4 | M28: 1 | N28: 311.54 | O28: 1 | P28: 44998 | Q28: 44998 | R28: =IF(ISBLANK(F28),"Missing",IFERROR(YEAR(F28),"Missing")) -> 2020 | S28: =IF(ISBLANK(E28),"Missing",IF(E28<6,"0-6mo",IF(E28<12,"6-12mo",IF(E28<24,"12-24mo","24mo+")))) -> 24mo+ | T28: =IF(ISBLANK(C28),0,IF(C28="Month-to-month",2,IF(C28="One year",1,0)))+IF(ISBLANK(I28),0,IF(I28<40,2,IF(I28<55,1,0)))+IF(ISBLANK(M28),0,IF(M28=1,3,0))+IF(ISBLANK(L28),0,IF(L28>=2,1,0))+IF(ISBLANK(E28),0,IF(E28<12,1,0)) -> 8 | U28: =IF((ISBLANK(B28)*1+ISBLANK(C28)*1+ISBLANK(D28)*1+ISBLANK(E28)*1+ISBLANK(F28)*1+ISBLANK(I28)*1+ISBLANK(J28)*1+ISBLANK(K28)*1+ISBLANK(L28)*1+ISBLANK(M28)*1+ISBLANK(N28)*1+ISBLANK(O28)*1)>0,"Missing Data","OK") -> OK | V28: =IF(T28>=6,"High Risk",IF(T28>=3,"Medium Risk","Low Risk")) -> High Risk
A29: CUST100118 | B29: Premium | C29: One year | D29: 40.18 | E29: 17 | F29: 43872 | G29: Credit card | H29: 1 | I29: 74.1 | J29: 20 | K29: 7 | L29: 0 | M29: 0 | N29: 683.06 | O29: 0 | Q29: 44389 | R29: =IF(ISBLANK(F29),"Missing",IFERROR(YEAR(F29),"Missing")) -> 2020 | S29: =IF(ISBLANK(E29),"Missing",IF(E29<6,"0-6mo",IF(E29<12,"6-12mo",IF(E29<24,"12-24mo","24mo+")))) -> 12-24mo | T29: =IF(ISBLANK(C29),0,IF(C29="Month-to-month",2,IF(C29="One year",1,0)))+IF(ISBLANK(I29),0,IF(I29<40,2,IF(I29<55,1,0)))+IF(ISBLANK(M29),0,IF(M29=1,3,0))+IF(ISBLANK(L29),0,IF(L29>=2,1,0))+IF(ISBLANK(E29),0,IF(E29<12,1,0)) -> 1 | U29: =IF((ISBLANK(B29)*1+ISBLANK(C29)*1+ISBLANK(D29)*1+ISBLANK(E29)*1+ISBLANK(F29)*1+ISBLANK(I29)*1+ISBLANK(J29)*1+ISBLANK(K29)*1+ISBLANK(L29)*1+ISBLANK(M29)*1+ISBLANK(N29)*1+ISBLANK(O29)*1)>0,"Missing Data","OK") -> OK | V29: =IF(T29>=6,"High Risk",IF(T29>=3,"Medium Risk","Low Risk")) -> Low Risk
A30: CUST101121 | B30: Premium | C30: Month-to-month | D30: 39.31 | E30: 59 | F30: 43876 | G30: Manual/Invoice | H30: 1 | I30: 52.6 | J30: 21 | K30: 6 | L30: 2 | M30: 1 | N30: 2319.29 | O30: 0 | Q30: 45671 | R30: =IF(ISBLANK(F30),"Missing",IFERROR(YEAR(F30),"Missing")) -> 2020 | S30: =IF(ISBLANK(E30),"Missing",IF(E30<6,"0-6mo",IF(E30<12,"6-12mo",IF(E30<24,"12-24mo","24mo+")))) -> 24mo+ | T30: =IF(ISBLANK(C30),0,IF(C30="Month-to-month",2,IF(C30="One year",1,0)))+IF(ISBLANK(I30),0,IF(I30<40,2,IF(I30<55,1,0)))+IF(ISBLANK(M30),0,IF(M30=1,3,0))+IF(ISBLANK(L30),0,IF(L30>=2,1,0))+IF(ISBLANK(E30),0,IF(E30<12,1,0)) -> 7 | U30: =IF((ISBLANK(B30)*1+ISBLANK(C30)*1+ISBLANK(D30)*1+ISBLANK(E30)*1+ISBLANK(F30)*1+ISBLANK(I30)*1+ISBLANK(J30)*1+ISBLANK(K30)*1+ISBLANK(L30)*1+ISBLANK(M30)*1+ISBLANK(N30)*1+ISBLANK(O30)*1)>0,"Missing Data","OK") -> OK | V30: =IF(T30>=6,"High Risk",IF(T30>=3,"Medium Risk","Low Risk")) -> High Risk
A31: CUST101027 | B31: Premium | C31: Month-to-month | D31: 39.72 | E31: 4 | F31: 43879 | G31: PayPal | H31: 1 | I31: 54 | J31: 20 | K31: 6 | L31: 3 | M31: 0 | N31: 158.88 | O31: 1 | P31: 44000 | Q31: 44000 | R31: =IF(ISBLANK(F31),"Missing",IFERROR(YEAR(F31),"Missing")) -> 2020 | S31: =IF(ISBLANK(E31),"Missing",IF(E31<6,"0-6mo",IF(E31<12,"6-12mo",IF(E31<24,"12-24mo","24mo+")))) -> 0-6mo | T31: =IF(ISBLANK(C31),0,IF(C31="Month-to-month",2,IF(C31="One year",1,0)))+IF(ISBLANK(I31),0,IF(I31<40,2,IF(I31<55,1,0)))+IF(ISBLANK(M31),0,IF(M31=1,3,0))+IF(ISBLANK(L31),0,IF(L31>=2,1,0))+IF(ISBLANK(E31),0,IF(E31<12,1,0)) -> 5 | U31: =IF((ISBLANK(B31)*1+ISBLANK(C31)*1+ISBLANK(D31)*1+ISBLANK(E31)*1+ISBLANK(F31)*1+ISBLANK(I31)*1+ISBLANK(J31)*1+ISBLANK(K31)*1+ISBLANK(L31)*1+ISBLANK(M31)*1+ISBLANK(N31)*1+ISBLANK(O31)*1)>0,"Missing Data","OK") -> OK | V31: =IF(T31>=6,"High Risk",IF(T31>=3,"Medium Risk","Low Risk")) -> Medium Risk
A32: CUST100565 | B32: Standard | C32: Month-to-month | D32: 21.08 | E32: 2 | F32: 43879 | G32: Credit card | H32: 1 | I32: 63.3 | J32: 18 | K32: 6 | L32: 3 | M32: 1 | N32: 42.16 | O32: 1 | P32: 43939 | Q32: 43939 | R32: =IF(ISBLANK(F32),"Missing",IFERROR(YEAR(F32),"Missing")) -> 2020 | S32: =IF(ISBLANK(E32),"Missing",IF(E32<6,"0-6mo",IF(E32<12,"6-12mo",IF(E32<24,"12-24mo","24mo+")))) -> 0-6mo | T32: =IF(ISBLANK(C32),0,IF(C32="Month-to-month",2,IF(C32="One year",1,0)))+IF(ISBLANK(I32),0,IF(I32<40,2,IF(I32<55,1,0)))+IF(ISBLANK(M32),0,IF(M32=1,3,0))+IF(ISBLANK(L32),0,IF(L32>=2,1,0))+IF(ISBLANK(E32),0,IF(E32<12,1,0)) -> 7 | U32: =IF((ISBLANK(B32)*1+ISBLANK(C32)*1+ISBLANK(D32)*1+ISBLANK(E32)*1+ISBLANK(F32)*1+ISBLANK(I32)*1+ISBLANK(J32)*1+ISBLANK(K32)*1+ISBLANK(L32)*1+ISBLANK(M32)*1+ISBLANK(N32)*1+ISBLANK(O32)*1)>0,"Missing Data","OK") -> OK | V32: =IF(T32>=6,"High Risk",IF(T32>=3,"Medium Risk","Low Risk")) -> High Risk
A33: CUST100731 | B33: Premium | C33: Month-to-month | D33: 40 | E33: 25 | F33: 43879 | G33: Credit card | H33: 0 | I33: 72.1 | J33: 21 | K33: 6 | L33: 2 | M33: 0 | N33: 1000 | O33: 0 | Q33: 44640 | R33: =IF(ISBLANK(F33),"Missing",IFERROR(YEAR(F33),"Missing")) -> 2020 | S33: =IF(ISBLANK(E33),"Missing",IF(E33<6,"0-6mo",IF(E33<12,"6-12mo",IF(E33<24,"12-24mo","24mo+")))) -> 24mo+ | T33: =IF(ISBLANK(C33),0,IF(C33="Month-to-month",2,IF(C33="One year",1,0)))+IF(ISBLANK(I33),0,IF(I33<40,2,IF(I33<55,1,0)))+IF(ISBLANK(M33),0,IF(M33=1,3,0))+IF(ISBLANK(L33),0,IF(L33>=2,1,0))+IF(ISBLANK(E33),0,IF(E33<12,1,0)) -> 3 | U33: =IF((ISBLANK(B33)*1+ISBLANK(C33)*1+ISBLANK(D33)*1+ISBLANK(E33)*1+ISBLANK(F33)*1+ISBLANK(I33)*1+ISBLANK(J33)*1+ISBLANK(K33)*1+ISBLANK(L33)*1+ISBLANK(M33)*1+ISBLANK(N33)*1+ISBLANK(O33)*1)>0,"Missing Data","OK") -> OK | V33: =IF(T33>=6,"High Risk",IF(T33>=3,"Medium Risk","Low Risk")) -> Medium Risk
A34: CUST101393 | B34: Standard | C34: Two year | D34: 20.38 | E34: 5 | F34: 43879 | G34: Credit card | H34: 1 | I34: 53 | J34: 21 | K34: 7 | L34: 1 | M34: 0 | N34: 101.9 | O34: 0 | Q34: 44031 | R34: =IF(ISBLANK(F34),"Missing",IFERROR(YEAR(F34),"Missing")) -> 2020 | S34: =IF(ISBLANK(E34),"Missing",IF(E34<6,"0-6mo",IF(E34<12,"6-12mo",IF(E34<24,"12-24mo","24mo+")))) -> 0-6mo | T34: =IF(ISBLANK(C34),0,IF(C34="Month-to-month",2,IF(C34="One year",1,0)))+IF(ISBLANK(I34),0,IF(I34<40,2,IF(I34<55,1,0)))+IF(ISBLANK(M34),0,IF(M34=1,3,0))+IF(ISBLANK(L34),0,IF(L34>=2,1,0))+IF(ISBLANK(E34),0,IF(E34<12,1,0)) -> 2 | U34: =IF((ISBLANK(B34)*1+ISBLANK(C34)*1+ISBLANK(D34)*1+ISBLANK(E34)*1+ISBLANK(F34)*1+ISBLANK(I34)*1+ISBLANK(J34)*1+ISBLANK(K34)*1+ISBLANK(L34)*1+ISBLANK(M34)*1+ISBLANK(N34)*1+ISBLANK(O34)*1)>0,"Missing Data","OK") -> OK | V34: =IF(T34>=6,"High Risk",IF(T34>=3,"Medium Risk","Low Risk")) -> Low Risk
A35: CUST101366 | B35: Standard | C35: One year | D35: 20.41 | E35: 17 | F35: 43881 | G35: Credit card | H35: 1 | I35: 47.8 | J35: 11 | K35: 7 | L35: 2 | M35: 0 | N35: 346.97 | O35: 0 | Q35: 44398 | R35: =IF(ISBLANK(F35),"Missing",IFERROR(YEAR(F35),"Missing")) -> 2020 | S35: =IF(ISBLANK(E35),"Missing",IF(E35<6,"0-6mo",IF(E35<12,"6-12mo",IF(E35<24,"12-24mo","24mo+")))) -> 12-24mo | T35: =IF(ISBLANK(C35),0,IF(C35="Month-to-month",2,IF(C35="One year",1,0)))+IF(ISBLANK(I35),0,IF(I35<40,2,IF(I35<55,1,0)))+IF(ISBLANK(M35),0,IF(M35=1,3,0))+IF(ISBLANK(L35),0,IF(L35>=2,1,0))+IF(ISBLANK(E35),0,IF(E35<12,1,0)) -> 3 | U35: =IF((ISBLANK(B35)*1+ISBLANK(C35)*1+ISBLANK(D35)*1+ISBLANK(E35)*1+ISBLANK(F35)*1+ISBLANK(I35)*1+ISBLANK(J35)*1+ISBLANK(K35)*1+ISBLANK(L35)*1+ISBLANK(M35)*1+ISBLANK(N35)*1+ISBLANK(O35)*1)>0,"Missing Data","OK") -> OK | V35: =IF(T35>=6,"High Risk",IF(T35>=3,"Medium Risk","Low Risk")) -> Medium Risk
A36: CUST100426 | B36: Basic | C36: One year | D36: 10.17 | E36: 0 | F36: 43885 | G36: Credit card | H36: 0 | I36: 62.5 | J36: 22 | K36: 7 | L36: 0 | M36: 0 | N36: 0 | O36: 0 | Q36: 43885 | R36: =IF(ISBLANK(F36),"Missing",IFERROR(YEAR(F36),"Missing")) -> 2020 | S36: =IF(ISBLANK(E36),"Missing",IF(E36<6,"0-6mo",IF(E36<12,"6-12mo",IF(E36<24,"12-24mo","24mo+")))) -> 0-6mo | T36: =IF(ISBLANK(C36),0,IF(C36="Month-to-month",2,IF(C36="One year",1,0)))+IF(ISBLANK(I36),0,IF(I36<40,2,IF(I36<55,1,0)))+IF(ISBLANK(M36),0,IF(M36=1,3,0))+IF(ISBLANK(L36),0,IF(L36>=2,1,0))+IF(ISBLANK(E36),0,IF(E36<12,1,0)) -> 2 | U36: =IF((ISBLANK(B36)*1+ISBLANK(C36)*1+ISBLANK(D36)*1+ISBLANK(E36)*1+ISBLANK(F36)*1+ISBLANK(I36)*1+ISBLANK(J36)*1+ISBLANK(K36)*1+ISBLANK(L36)*1+ISBLANK(M36)*1+ISBLANK(N36)*1+ISBLANK(O36)*1)>0,"Missing Data","OK") -> OK | V36: =IF(T36>=6,"High Risk",IF(T36>=3,"Medium Risk","Low Risk")) -> Low Risk
A37: CUST101044 | B37: Premium | C37: Month-to-month | D37: 39.03 | E37: 11 | F37: 43885 | G37: Credit card | H37: 0 | I37: 69 | J37: 29 | K37: 9 | L37: 2 | M37: 1 | N37: 429.33 | O37: 1 | P37: 44219 | Q37: 44219 | R37: =IF(ISBLANK(F37),"Missing",IFERROR(YEAR(F37),"Missing")) -> 2020 | S37: =IF(ISBLANK(E37),"Missing",IF(E37<6,"0-6mo",IF(E37<12,"6-12mo",IF(E37<24,"12-24mo","24mo+")))) -> 6-12mo | T37: =IF(ISBLANK(C37),0,IF(C37="Month-to-month",2,IF(C37="One year",1,0)))+IF(ISBLANK(I37),0,IF(I37<40,2,IF(I37<55,1,0)))+IF(ISBLANK(M37),0,IF(M37=1,3,0))+IF(ISBLANK(L37),0,IF(L37>=2,1,0))+IF(ISBLANK(E37),0,IF(E37<12,1,0)) -> 7 | U37: =IF((ISBLANK(B37)*1+ISBLANK(C37)*1+ISBLANK(D37)*1+ISBLANK(E37)*1+ISBLANK(F37)*1+ISBLANK(I37)*1+ISBLANK(J37)*1+ISBLANK(K37)*1+ISBLANK(L37)*1+ISBLANK(M37)*1+ISBLANK(N37)*1+ISBLANK(O37)*1)>0,"Missing Data","OK") -> OK | V37: =IF(T37>=6,"High Risk",IF(T37>=3,"Medium Risk","Low Risk")) -> High Risk
A38: CUST100867 | B38: Basic | C38: Two year | D38: 11.23 | E38: 16 | F38: 43889 | G38: PayPal | H38: 1 | I38: 50.9 | J38: 17 | K38: 6 | L38: 3 | M38: 0 | N38: 179.68 | O38: 0 | Q38: 44376 | R38: =IF(ISBLANK(F38),"Missing",IFERROR(YEAR(F38),"Missing")) -> 2020 | S38: =IF(ISBLANK(E38),"Missing",IF(E38<6,"0-6mo",IF(E38<12,"6-12mo",IF(E38<24,"12-24mo","24mo+")))) -> 12-24mo | T38: =IF(ISBLANK(C38),0,IF(C38="Month-to-month",2,IF(C38="One year",1,0)))+IF(ISBLANK(I38),0,IF(I38<40,2,IF(I38<55,1,0)))+IF(ISBLANK(M38),0,IF(M38=1,3,0))+IF(ISBLANK(L38),0,IF(L38>=2,1,0))+IF(ISBLANK(E38),0,IF(E38<12,1,0)) -> 2 | U38: =IF((ISBLANK(B38)*1+ISBLANK(C38)*1+ISBLANK(D38)*1+ISBLANK(E38)*1+ISBLANK(F38)*1+ISBLANK(I38)*1+ISBLANK(J38)*1+ISBLANK(K38)*1+ISBLANK(L38)*1+ISBLANK(M38)*1+ISBLANK(N38)*1+ISBLANK(O38)*1)>0,"Missing Data","OK") -> OK | V38: =IF(T38>=6,"High Risk",IF(T38>=3,"Medium Risk","Low Risk")) -> Low Risk
A39: CUST100652 | B39: Standard | C39: Month-to-month | D39: 21.6 | E39: 2 | F39: 43890 | G39: Credit card | H39: 1 | I39: 55.6 | J39: 18 | K39: 7 | L39: 0 | M39: 0 | N39: 43.2 | O39: 0 | Q39: 43950 | R39: =IF(ISBLANK(F39),"Missing",IFERROR(YEAR(F39),"Missing")) -> 2020 | S39: =IF(ISBLANK(E39),"Missing",IF(E39<6,"0-6mo",IF(E39<12,"6-12mo",IF(E39<24,"12-24mo","24mo+")))) -> 0-6mo | T39: =IF(ISBLANK(C39),0,IF(C39="Month-to-month",2,IF(C39="One year",1,0)))+IF(ISBLANK(I39),0,IF(I39<40,2,IF(I39<55,1,0)))+IF(ISBLANK(M39),0,IF(M39=1,3,0))+IF(ISBLANK(L39),0,IF(L39>=2,1,0))+IF(ISBLANK(E39),0,IF(E39<12,1,0)) -> 3 | U39: =IF((ISBLANK(B39)*1+ISBLANK(C39)*1+ISBLANK(D39)*1+ISBLANK(E39)*1+ISBLANK(F39)*1+ISBLANK(I39)*1+ISBLANK(J39)*1+ISBLANK(K39)*1+ISBLANK(L39)*1+ISBLANK(M39)*1+ISBLANK(N39)*1+ISBLANK(O39)*1)>0,"Missing Data","OK") -> OK | V39: =IF(T39>=6,"High Risk",IF(T39>=3,"Medium Risk","Low Risk")) -> Medium Risk
A40: CUST100638 | B40: Basic | C40: Month-to-month | D40: 11.07 | E40: 8 | F40: 43892 | G40: Credit card | H40: 1 | I40: 43.4 | J40: 14 | K40: 3 | L40: 2 | M40: 0 | N40: 88.56 | O40: 1 | P40: 44135 | Q40: 44135 | R40: =IF(ISBLANK(F40),"Missing",IFERROR(YEAR(F40),"Missing")) -> 2020 | S40: =IF(ISBLANK(E40),"Missing",IF(E40<6,"0-6mo",IF(E40<12,"6-12mo",IF(E40<24,"12-24mo","24mo+")))) -> 6-12mo | T40: =IF(ISBLANK(C40),0,IF(C40="Month-to-month",2,IF(C40="One year",1,0)))+IF(ISBLANK(I40),0,IF(I40<40,2,IF(I40<55,1,0)))+IF(ISBLANK(M40),0,IF(M40=1,3,0))+IF(ISBLANK(L40),0,IF(L40>=2,1,0))+IF(ISBLANK(E40),0,IF(E40<12,1,0)) -> 5 | U40: =IF((ISBLANK(B40)*1+ISBLANK(C40)*1+ISBLANK(D40)*1+ISBLANK(E40)*1+ISBLANK(F40)*1+ISBLANK(I40)*1+ISBLANK(J40)*1+ISBLANK(K40)*1+ISBLANK(L40)*1+ISBLANK(M40)*1+ISBLANK(N40)*1+ISBLANK(O40)*1)>0,"Missing Data","OK") -> OK | V40: =IF(T40>=6,"High Risk",IF(T40>=3,"Medium Risk","Low Risk")) -> Medium Risk
...

Sheet cleaned_data
A1: Customer_id | B1: Plan Type | C1: Contract Type | D1: Monthly Charge | E1: Tenure | F1: Signup date | G1: Payment_method | H1: Autopay | I1: usage_score | J1: login_per_month | K1: Feature_used | L1: Support_tickets | M1: complaint_unresolved | N1: Total Revenue | O1: Churned | P1: Duplicate_flag | Q1: Cleaning_notes
A2: =TRIM(customer_churn_dataset!A2) -> CUST100500 | B2: =PROPER(TRIM(customer_churn_dataset!B2)) -> Standard | C2: =PROPER(TRIM(customer_churn_dataset!C2)) -> Month-To-Month | D2: =IF(ISBLANK(customer_churn_dataset!D2),ROUND(MEDIAN(customer_churn_dataset!D$2:D$1501),2),IF(customer_churn_dataset!D2<0,ABS(customer_churn_dataset!D2),customer_churn_dataset!D2)) -> 21.31 | E2: =IF(ISBLANK(customer_churn_dataset!E2),0,MAX(0,customer_churn_dataset!E2)) -> 20 | F2: =IF(ISBLANK(customer_churn_dataset!F2),"",customer_churn_dataset!F2) -> 43833 | G2: =PROPER(TRIM(customer_churn_dataset!G2)) -> Credit Card | H2: =IF(ISBLANK(customer_churn_dataset!H2),0,customer_churn_dataset!H2) -> 1 | I2: =IF(ISBLANK(customer_churn_dataset!I2),ROUND(MEDIAN(customer_churn_dataset!I$2:I$1501),1),MIN(100,MAX(0,customer_churn_dataset!I2))) -> 78.8 | J2: =IF(ISBLANK(customer_churn_dataset!J2),0,MAX(0,customer_churn_dataset!J2)) -> 8 | K2: =IF(ISBLANK(customer_churn_dataset!K2),0,MIN(10,MAX(0,customer_churn_dataset!K2))) -> 8 | L2: =IF(ISBLANK(customer_churn_dataset!L2),0,MAX(0,customer_churn_dataset!L2)) -> 2 | M2: =IF(ISBLANK(customer_churn_dataset!M2),0,customer_churn_dataset!M2) -> 1 | N2: =IF(ISBLANK(customer_churn_dataset!N2),0,MAX(0,customer_churn_dataset!N2)) -> 426.2 | O2: =IF(ISBLANK(customer_churn_dataset!O2),0,customer_churn_dataset!O2) -> 0 | P2: =IF(COUNTIF(customer_churn_dataset!$A$2:$A$1501,customer_churn_dataset!A2)>1,"Duplicate","Unique") -> Unique
A3: =TRIM(customer_churn_dataset!A3) -> CUST101041 | B3: =PROPER(TRIM(customer_churn_dataset!B3)) -> Standard | C3: =PROPER(TRIM(customer_churn_dataset!C3)) -> Month-To-Month | D3: =IF(ISBLANK(customer_churn_dataset!D3),ROUND(MEDIAN(customer_churn_dataset!D$2:D$1501),2),IF(customer_churn_dataset!D3<0,ABS(customer_churn_dataset!D3),customer_churn_dataset!D3)) -> 19.8 | E3: =IF(ISBLANK(customer_churn_dataset!E3),0,MAX(0,customer_churn_dataset!E3)) -> 33 | F3: =IF(ISBLANK(customer_churn_dataset!F3),"",customer_churn_dataset!F3) -> 43833 | G3: =PROPER(TRIM(customer_churn_dataset!G3)) -> Manual/Invoice | H3: =IF(ISBLANK(customer_churn_dataset!H3),0,customer_churn_dataset!H3) -> 1 | I3: =IF(ISBLANK(customer_churn_dataset!I3),ROUND(MEDIAN(customer_churn_dataset!I$2:I$1501),1),MIN(100,MAX(0,customer_churn_dataset!I3))) -> 46.1 | J3: =IF(ISBLANK(customer_churn_dataset!J3),0,MAX(0,customer_churn_dataset!J3)) -> 20 | K3: =IF(ISBLANK(customer_churn_dataset!K3),0,MIN(10,MAX(0,customer_churn_dataset!K3))) -> 4 | L3: =IF(ISBLANK(customer_churn_dataset!L3),0,MAX(0,customer_churn_dataset!L3)) -> 0 | M3: =IF(ISBLANK(customer_churn_dataset!M3),0,customer_churn_dataset!M3) -> 0 | N3: =IF(ISBLANK(customer_churn_dataset!N3),0,MAX(0,customer_churn_dataset!N3)) -> 653.4 | O3: =IF(ISBLANK(customer_churn_dataset!O3),0,customer_churn_dataset!O3) -> 0 | P3: =IF(COUNTIF(customer_churn_dataset!$A$2:$A$1501,customer_churn_dataset!A3)>1,"Duplicate","Unique") -> Unique
A4: =TRIM(customer_churn_dataset!A4) -> CUST100305 | B4: =PROPER(TRIM(customer_churn_dataset!B4)) -> Premium | C4: =PROPER(TRIM(customer_churn_dataset!C4)) -> Month-To-Month | D4: =IF(ISBLANK(customer_churn_dataset!D4),ROUND(MEDIAN(customer_churn_dataset!D$2:D$1501),2),IF(customer_churn_dataset!D4<0,ABS(customer_churn_dataset!D4),customer_churn_dataset!D4)) -> 40.58 | E4: =IF(ISBLANK(customer_churn_dataset!E4),0,MAX(0,customer_churn_dataset!E4)) -> 18 | F4: =IF(ISBLANK(customer_churn_dataset!F4),"",customer_churn_dataset!F4) -> 43834 | G4: =PROPER(TRIM(customer_churn_dataset!G4)) -> Bank Transfer | H4: =IF(ISBLANK(customer_churn_dataset!H4),0,customer_churn_dataset!H4) -> 1 | I4: =IF(ISBLANK(customer_churn_dataset!I4),ROUND(MEDIAN(customer_churn_dataset!I$2:I$1501),1),MIN(100,MAX(0,customer_churn_dataset!I4))) -> 49.8 | J4: =IF(ISBLANK(customer_churn_dataset!J4),0,MAX(0,customer_churn_dataset!J4)) -> 17 | K4: =IF(ISBLANK(customer_churn_dataset!K4),0,MIN(10,MAX(0,customer_churn_dataset!K4))) -> 6 | L4: =IF(ISBLANK(customer_churn_dataset!L4),0,MAX(0,customer_churn_dataset!L4)) -> 3 | M4: =IF(ISBLANK(customer_churn_dataset!M4),0,customer_churn_dataset!M4) -> 0 | N4: =IF(ISBLANK(customer_churn_dataset!N4),0,MAX(0,customer_churn_dataset!N4)) -> 730.44 | O4: =IF(ISBLANK(customer_churn_dataset!O4),0,customer_churn_dataset!O4) -> 0 | P4: =IF(COUNTIF(customer_churn_dataset!$A$2:$A$1501,customer_churn_dataset!A4)>1,"Duplicate","Unique") -> Unique
A5: =TRIM(customer_churn_dataset!A5) -> CUST101045 | B5: =PROPER(TRIM(customer_churn_dataset!B5)) -> Standard | C5: =PROPER(TRIM(customer_churn_dataset!C5)) -> Month-To-Month | D5: =IF(ISBLANK(customer_churn_dataset!D5),ROUND(MEDIAN(customer_churn_dataset!D$2:D$1501),2),IF(customer_churn_dataset!D5<0,ABS(customer_churn_dataset!D5),customer_churn_dataset!D5)) -> 20.46 | E5: =IF(ISBLANK(customer_churn_dataset!E5),0,MAX(0,customer_churn_dataset!E5)) -> 57 | F5: =IF(ISBLANK(customer_churn_dataset!F5),"",customer_churn_dataset!F5) -> 43837 | G5: =PROPER(TRIM(customer_churn_dataset!G5)) -> Credit Card | H5: =IF(ISBLANK(customer_churn_dataset!H5),0,customer_churn_dataset!H5) -> 0 | I5: =IF(ISBLANK(customer_churn_dataset!I5),ROUND(MEDIAN(customer_churn_dataset!I$2:I$1501),1),MIN(100,MAX(0,customer_churn_dataset!I5))) -> 42.4 | J5: =IF(ISBLANK(customer_churn_dataset!J5),0,MAX(0,customer_churn_dataset!J5)) -> 10 | K5: =IF(ISBLANK(customer_churn_dataset!K5),0,MIN(10,MAX(0,customer_churn_dataset!K5))) -> 3 | L5: =IF(ISBLANK(customer_churn_dataset!L5),0,MAX(0,customer_churn_dataset!L5)) -> 1 | M5: =IF(ISBLANK(customer_churn_dataset!M5),0,customer_churn_dataset!M5) -> 0 | N5: =IF(ISBLANK(customer_churn_dataset!N5),0,MAX(0,customer_churn_dataset!N5)) -> 1166.22 | O5: =IF(ISBLANK(customer_churn_dataset!O5),0,customer_churn_dataset!O5) -> 0 | P5: =IF(COUNTIF(customer_churn_dataset!$A$2:$A$1501,customer_churn_dataset!A5)>1,"Duplicate","Unique") -> Unique
A6: =TRIM(customer_churn_dataset!A6) -> CUST101341 | B6: =PROPER(TRIM(customer_churn_dataset!B6)) -> Standard | C6: =PROPER(TRIM(customer_churn_dataset!C6)) -> Month-To-Month | D6: =IF(ISBLANK(customer_churn_dataset!D6),ROUND(MEDIAN(customer_churn_dataset!D$2:D$1501),2),IF(customer_churn_dataset!D6<0,ABS(customer_churn_dataset!D6),customer_churn_dataset!D6)) -> 20.96 | E6: =IF(ISBLANK(customer_churn_dataset!E6),0,MAX(0,customer_churn_dataset!E6)) -> 9 | F6: =IF(ISBLANK(customer_churn_dataset!F6),"",customer_churn_dataset!F6) -> 43837 | G6: =PROPER(TRIM(customer_churn_dataset!G6)) -> Bank Transfer | H6: =IF(ISBLANK(customer_churn_dataset!H6),0,customer_churn_dataset!H6) -> 1 | I6: =IF(ISBLANK(customer_churn_dataset!I6),ROUND(MEDIAN(customer_churn_dataset!I$2:I$1501),1),MIN(100,MAX(0,customer_churn_dataset!I6))) -> 54.2 | J6: =IF(ISBLANK(customer_churn_dataset!J6),0,MAX(0,customer_churn_dataset!J6)) -> 17 | K6: =IF(ISBLANK(customer_churn_dataset!K6),0,MIN(10,MAX(0,customer_churn_dataset!K6))) -> 6 | L6: =IF(ISBLANK(customer_churn_dataset!L6),0,MAX(0,customer_churn_dataset!L6)) -> 2 | M6: =IF(ISBLANK(customer_churn_dataset!M6),0,customer_churn_dataset!M6) -> 1 | N6: =IF(ISBLANK(customer_churn_dataset!N6),0,MAX(0,customer_churn_dataset!N6)) -> 188.64 | O6: =IF(ISBLANK(customer_churn_dataset!O6),0,customer_churn_dataset!O6) -> 0 | P6: =IF(COUNTIF(customer_churn_dataset!$A$2:$A$1501,customer_churn_dataset!A6)>1,"Duplicate","Unique") -> Unique
A7: =TRIM(customer_churn_dataset!A7) -> CUST101313 | B7: =PROPER(TRIM(customer_churn_dataset!B7)) -> Premium | C7: =PROPER(TRIM(customer_churn_dataset!C7)) -> One Year | D7: =IF(ISBLANK(customer_churn_dataset!D7),ROUND(MEDIAN(customer_churn_dataset!D$2:D$1501),2),IF(customer_churn_dataset!D7<0,ABS(customer_churn_dataset!D7),customer_churn_dataset!D7)) -> 38.61 | E7: =IF(ISBLANK(customer_churn_dataset!E7),0,MAX(0,customer_churn_dataset!E7)) -> 8 | F7: =IF(ISBLANK(customer_churn_dataset!F7),"",customer_churn_dataset!F7) -> 43839 | G7: =PROPER(TRIM(customer_churn_dataset!G7)) -> Credit Card | H7: =IF(ISBLANK(customer_churn_dataset!H7),0,customer_churn_dataset!H7) -> 0 | I7: =IF(ISBLANK(customer_churn_dataset!I7),ROUND(MEDIAN(customer_churn_dataset!I$2:I$1501),1),MIN(100,MAX(0,customer_churn_dataset!I7))) -> 45.7 | J7: =IF(ISBLANK(customer_churn_dataset!J7),0,MAX(0,customer_churn_dataset!J7)) -> 14 | K7: =IF(ISBLANK(customer_churn_dataset!K7),0,MIN(10,MAX(0,customer_churn_dataset!K7))) -> 2 | L7: =IF(ISBLANK(customer_churn_dataset!L7),0,MAX(0,customer_churn_dataset!L7)) -> 1 | M7: =IF(ISBLANK(customer_churn_dataset!M7),0,customer_churn_dataset!M7) -> 1 | N7: =IF(ISBLANK(customer_churn_dataset!N7),0,MAX(0,customer_churn_dataset!N7)) -> 308.88 | O7: =IF(ISBLANK(customer_churn_dataset!O7),0,customer_churn_dataset!O7) -> 1 | P7: =IF(COUNTIF(customer_churn_dataset!$A$2:$A$1501,customer_churn_dataset!A7)>1,"Duplicate","Unique") -> Unique
A8: =TRIM(customer_churn_dataset!A8) -> CUST100592 | B8: =PROPER(TRIM(customer_churn_dataset!B8)) -> Basic | C8: =PROPER(TRIM(customer_churn_dataset!C8)) -> Month-To-Month | D8: =IF(ISBLANK(customer_churn_dataset!D8),ROUND(MEDIAN(customer_churn_dataset!D$2:D$1501),2),IF(customer_churn_dataset!D8<0,ABS(customer_churn_dataset!D8),customer_churn_dataset!D8)) -> 9.34 | E8: =IF(ISBLANK(customer_churn_dataset!E8),0,MAX(0,customer_churn_dataset!E8)) -> 72 | F8: =IF(ISBLANK(customer_churn_dataset!F8),"",customer_churn_dataset!F8) -> 43842 | G8: =PROPER(TRIM(customer_churn_dataset!G8)) -> Bank Transfer | H8: =IF(ISBLANK(customer_churn_dataset!H8),0,customer_churn_dataset!H8) -> 0 | I8: =IF(ISBLANK(customer_churn_dataset!I8),ROUND(MEDIAN(customer_churn_dataset!I$2:I$1501),1),MIN(100,MAX(0,customer_churn_dataset!I8))) -> 72.8 | J8: =IF(ISBLANK(customer_churn_dataset!J8),0,MAX(0,customer_churn_dataset!J8)) -> 25 | K8: =IF(ISBLANK(customer_churn_dataset!K8),0,MIN(10,MAX(0,customer_churn_dataset!K8))) -> 8 | L8: =IF(ISBLANK(customer_churn_dataset!L8),0,MAX(0,customer_churn_dataset!L8)) -> 1 | M8: =IF(ISBLANK(customer_churn_dataset!M8),0,customer_churn_dataset!M8) -> 0 | N8: =IF(ISBLANK(customer_churn_dataset!N8),0,MAX(0,customer_churn_dataset!N8)) -> 672.48 | O8: =IF(ISBLANK(customer_churn_dataset!O8),0,customer_churn_dataset!O8) -> 0 | P8: =IF(COUNTIF(customer_churn_dataset!$A$2:$A$1501,customer_churn_dataset!A8)>1,"Duplicate","Unique") -> Unique
A9: =TRIM(customer_churn_dataset!A9) -> CUST101076 | B9: =PROPER(TRIM(customer_churn_dataset!B9)) -> Basic | C9: =PROPER(TRIM(customer_churn_dataset!C9)) -> Month-To-Month | D9: =IF(ISBLANK(customer_churn_dataset!D9),ROUND(MEDIAN(customer_churn_dataset!D$2:D$1501),2),IF(customer_churn_dataset!D9<0,ABS(customer_churn_dataset!D9),customer_churn_dataset!D9)) -> 10 | E9: =IF(ISBLANK(customer_churn_dataset!E9),0,MAX(0,customer_churn_dataset!E9)) -> 0 | F9: =IF(ISBLANK(customer_churn_dataset!F9),"",customer_churn_dataset!F9) -> 43843 | G9: =PROPER(TRIM(customer_churn_dataset!G9)) -> Credit Card | H9: =IF(ISBLANK(customer_churn_dataset!H9),0,customer_churn_dataset!H9) -> 0 | I9: =IF(ISBLANK(customer_churn_dataset!I9),ROUND(MEDIAN(customer_churn_dataset!I$2:I$1501),1),MIN(100,MAX(0,customer_churn_dataset!I9))) -> 33.9 | J9: =IF(ISBLANK(customer_churn_dataset!J9),0,MAX(0,customer_churn_dataset!J9)) -> 9 | K9: =IF(ISBLANK(customer_churn_dataset!K9),0,MIN(10,MAX(0,customer_churn_dataset!K9))) -> 4 | L9: =IF(ISBLANK(customer_churn_dataset!L9),0,MAX(0,customer_churn_dataset!L9)) -> 1 | M9: =IF(ISBLANK(customer_churn_dataset!M9),0,customer_churn_dataset!M9) -> 0 | N9: =IF(ISBLANK(customer_churn_dataset!N9),0,MAX(0,customer_churn_dataset!N9)) -> 0 | O9: =IF(ISBLANK(customer_churn_dataset!O9),0,customer_churn_dataset!O9) -> 1 | P9: =IF(COUNTIF(customer_churn_dataset!$A$2:$A$1501,customer_churn_dataset!A9)>1,"Duplicate","Unique") -> Unique
A10: =TRIM(customer_churn_dataset!A10) -> CUST101481 | B10: =PROPER(TRIM(customer_churn_dataset!B10)) -> Basic | C10: =PROPER(TRIM(customer_churn_dataset!C10)) -> Month-To-Month | D10: =IF(ISBLANK(customer_churn_dataset!D10),ROUND(MEDIAN(customer_churn_dataset!D$2:D$1501),2),IF(customer_churn_dataset!D10<0,ABS(customer_churn_dataset!D10),customer_churn_dataset!D10)) -> 9.77 | E10: =IF(ISBLANK(customer_churn_dataset!E10),0,MAX(0,customer_churn_dataset!E10)) -> 72 | F10: =IF(ISBLANK(customer_churn_dataset!F10),"",customer_churn_dataset!F10) -> 43843 | G10: =PROPER(TRIM(customer_churn_dataset!G10)) -> Paypal | H10: =IF(ISBLANK(customer_churn_dataset!H10),0,customer_churn_dataset!H10) -> 0 | I10: =IF(ISBLANK(customer_churn_dataset!I10),ROUND(MEDIAN(customer_churn_dataset!I$2:I$1501),1),MIN(100,MAX(0,customer_churn_dataset!I10))) -> 38.9 | J10: =IF(ISBLANK(customer_churn_dataset!J10),0,MAX(0,customer_churn_dataset!J10)) -> 10 | K10: =IF(ISBLANK(customer_churn_dataset!K10),0,MIN(10,MAX(0,customer_churn_dataset!K10))) -> 4 | L10: =IF(ISBLANK(customer_churn_dataset!L10),0,MAX(0,customer_churn_dataset!L10)) -> 1 | M10: =IF(ISBLANK(customer_churn_dataset!M10),0,customer_churn_dataset!M10) -> 1 | N10: =IF(ISBLANK(customer_churn_dataset!N10),0,MAX(0,customer_churn_dataset!N10)) -> 703.44 | O10: =IF(ISBLANK(customer_churn_dataset!O10),0,customer_churn_dataset!O10) -> 0 | P10: =IF(COUNTIF(customer_churn_dataset!$A$2:$A$1501,customer_churn_dataset!A10)>1,"Duplicate","Unique") -> Unique
A11: =TRIM(customer_churn_dataset!A11) -> CUST100688 | B11: =PROPER(TRIM(customer_churn_dataset!B11)) -> Standard | C11: =PROPER(TRIM(customer_churn_dataset!C11)) -> One Year | D11: =IF(ISBLANK(customer_churn_dataset!D11),ROUND(MEDIAN(customer_churn_dataset!D$2:D$1501),2),IF(customer_churn_dataset!D11<0,ABS(customer_churn_dataset!D11),customer_churn_dataset!D11)) -> 20.96 | E11: =IF(ISBLANK(customer_churn_dataset!E11),0,MAX(0,customer_churn_dataset!E11)) -> 39 | F11: =IF(ISBLANK(customer_churn_dataset!F11),"",customer_churn_dataset!F11) -> 43845 | G11: =PROPER(TRIM(customer_churn_dataset!G11)) -> Paypal | H11: =IF(ISBLANK(customer_churn_dataset!H11),0,customer_churn_dataset!H11) -> 1 | I11: =IF(ISBLANK(customer_churn_dataset!I11),ROUND(MEDIAN(customer_churn_dataset!I$2:I$1501),1),MIN(100,MAX(0,customer_churn_dataset!I11))) -> 42.3 | J11: =IF(ISBLANK(customer_churn_dataset!J11),0,MAX(0,customer_churn_dataset!J11)) -> 10 | K11: =IF(ISBLANK(customer_churn_dataset!K11),0,MIN(10,MAX(0,customer_churn_dataset!K11))) -> 5 | L11: =IF(ISBLANK(customer_churn_dataset!L11),0,MAX(0,customer_churn_dataset!L11)) -> 1 | M11: =IF(ISBLANK(customer_churn_dataset!M11),0,customer_churn_dataset!M11) -> 1 | N11: =IF(ISBLANK(customer_churn_dataset!N11),0,MAX(0,customer_churn_dataset!N11)) -> 817.44 | O11: =IF(ISBLANK(customer_churn_dataset!O11),0,customer_churn_dataset!O11) -> 0 | P11: =IF(COUNTIF(customer_churn_dataset!$A$2:$A$1501,customer_churn_dataset!A11)>1,"Duplicate","Unique") -> Unique
A12: =TRIM(customer_churn_dataset!A12) -> CUST100968 | B12: =PROPER(TRIM(customer_churn_dataset!B12)) -> Standard | C12: =PROPER(TRIM(customer_churn_dataset!C12)) -> Month-To-Month | D12: =IF(ISBLANK(customer_churn_dataset!D12),ROUND(MEDIAN(customer_churn_dataset!D$2:D$1501),2),IF(customer_churn_dataset!D12<0,ABS(customer_churn_dataset!D12),customer_churn_dataset!D12)) -> 20.71 | E12: =IF(ISBLANK(customer_churn_dataset!E12),0,MAX(0,customer_churn_dataset!E12)) -> 35 | F12: =IF(ISBLANK(customer_churn_dataset!F12),"",customer_churn_dataset!F12) -> 43845 | G12: =PROPER(TRIM(customer_churn_dataset!G12)) -> Credit Card | H12: =IF(ISBLANK(customer_churn_dataset!H12),0,customer_churn_dataset!H12) -> 0 | I12: =IF(ISBLANK(customer_churn_dataset!I12),ROUND(MEDIAN(customer_churn_dataset!I$2:I$1501),1),MIN(100,MAX(0,customer_churn_dataset!I12))) -> 76.7 | J12: =IF(ISBLANK(customer_churn_dataset!J12),0,MAX(0,customer_churn_dataset!J12)) -> 25 | K12: =IF(ISBLANK(customer_churn_dataset!K12),0,MIN(10,MAX(0,customer_churn_dataset!K12))) -> 6 | L12: =IF(ISBLANK(customer_churn_dataset!L12),0,MAX(0,customer_churn_dataset!L12)) -> 0 | M12: =IF(ISBLANK(customer_churn_dataset!M12),0,customer_churn_dataset!M12) -> 0 | N12: =IF(ISBLANK(customer_churn_dataset!N12),0,MAX(0,customer_churn_dataset!N12)) -> 724.85 | O12: =IF(ISBLANK(customer_churn_dataset!O12),0,customer_churn_dataset!O12) -> 0 | P12: =IF(COUNTIF(customer_churn_dataset!$A$2:$A$1501,customer_churn_dataset!A12)>1,"Duplicate","Unique") -> Unique
A13: =TRIM(customer_churn_dataset!A13) -> CUST101408 | B13: =PROPER(TRIM(customer_churn_dataset!B13)) -> Standard | C13: =PROPER(TRIM(customer_churn_dataset!C13)) -> Month-To-Month | D13: =IF(ISBLANK(customer_churn_dataset!D13),ROUND(MEDIAN(customer_churn_dataset!D$2:D$1501),2),IF(customer_churn_dataset!D13<0,ABS(customer_churn_dataset!D13),customer_churn_dataset!D13)) -> 20.85 | E13: =IF(ISBLANK(customer_churn_dataset!E13),0,MAX(0,customer_churn_dataset!E13)) -> 19 | F13: =IF(ISBLANK(customer_churn_dataset!F13),"",customer_churn_dataset!F13) -> 43845 | G13: =PROPER(TRIM(customer_churn_dataset!G13)) -> Credit Card | H13: =IF(ISBLANK(customer_churn_dataset!H13),0,customer_churn_dataset!H13) -> 1 | I13: =IF(ISBLANK(customer_churn_dataset!I13),ROUND(MEDIAN(customer_churn_dataset!I$2:I$1501),1),MIN(100,MAX(0,customer_churn_dataset!I13))) -> 47.5 | J13: =IF(ISBLANK(customer_churn_dataset!J13),0,MAX(0,customer_churn_dataset!J13)) -> 20 | K13: =IF(ISBLANK(customer_churn_dataset!K13),0,MIN(10,MAX(0,customer_churn_dataset!K13))) -> 6 | L13: =IF(ISBLANK(customer_churn_dataset!L13),0,MAX(0,customer_churn_dataset!L13)) -> 3 | M13: =IF(ISBLANK(customer_churn_dataset!M13),0,customer_churn_dataset!M13) -> 0 | N13: =IF(ISBLANK(customer_churn_dataset!N13),0,MAX(0,customer_churn_dataset!N13)) -> 396.15 | O13: =IF(ISBLANK(customer_churn_dataset!O13),0,customer_churn_dataset!O13) -> 0 | P13: =IF(COUNTIF(customer_churn_dataset!$A$2:$A$1501,customer_churn_dataset!A13)>1,"Duplicate","Unique") -> Unique
... A1501: =TRIM(customer_churn_dataset!A1501) -> CUST100898 | B1501: =PROPER(TRIM(customer_churn_dataset!B1501)) -> Basic | C1501: =PROPER(TRIM(customer_churn_dataset!C1501)) -> One Year | D1501: =IF(ISBLANK(customer_churn_dataset!D1501),ROUND(MEDIAN(customer_churn_dataset!D$2:D$1501),2),IF(customer_churn_dataset!D1501<0,ABS(customer_churn_dataset!D1501),customer_churn_dataset!D1501)) -> 10.25 | E1501: =IF(ISBLANK(customer_churn_dataset!E1501),0,MAX(0,customer_churn_dataset!E1501)) -> 45 | F1501: =IF(ISBLANK(customer_churn_dataset!F1501),"",customer_churn_dataset!F1501) -> 45829 | G1501: =PROPER(TRIM(customer_churn_dataset!G1501)) -> Bank Transfer | H1501: =IF(ISBLANK(customer_churn_dataset!H1501),0,customer_churn_dataset!H1501) -> 1 | I1501: =IF(ISBLANK(customer_churn_dataset!I1501),ROUND(MEDIAN(customer_churn_dataset!I$2:I$1501),1),MIN(100,MAX(0,customer_churn_dataset!I1501))) -> 37.5 | J1501: =IF(ISBLANK(customer_churn_dataset!J1501),0,MAX(0,customer_churn_dataset!J1501)) -> 7 | K1501: =IF(ISBLANK(customer_churn_dataset!K1501),0,MIN(10,MAX(0,customer_churn_dataset!K1501))) -> 3 | L1501: =IF(ISBLANK(customer_churn_dataset!L1501),0,MAX(0,customer_churn_dataset!L1501)) -> 0 | M1501: =IF(ISBLANK(customer_churn_dataset!M1501),0,customer_churn_dataset!M1501) -> 0 | N1501: =IF(ISBLANK(customer_churn_dataset!N1501),0,MAX(0,customer_churn_dataset!N1501)) -> 461.25 | O1501: =IF(ISBLANK(customer_churn_dataset!O1501),0,customer_churn_dataset!O1501) -> 0 | P1501: =IF(COUNTIF(customer_churn_dataset!$A$2:$A$1501,customer_churn_dataset!A1501)>1,"Duplicate","Unique") -> Unique

Sheet Summary
A1: Customer Churn Analysis - Executive Summary
A3: Overall Metrics
A4: Metric | B4: Value
A5: Total Customers | B5: =COUNTA(customer_churn_dataset!$A$2:$A$1501) -> 1500
A6: Churned Customers | B6: =COUNTIF(customer_churn_dataset!$O$2:$O$1501,1) -> 284
A7: Overall Churn Rate | B7: =B6/B5 -> 0.18933333
A9: Data Quality Check
A10: Check | B10: Count
A11: Rows with Complete Data | B11: =COUNTA(customer_churn_dataset!$A$2:$A$1501) -> 1500
A12: Rows with Missing Data | B12: =COUNTIF(customer_churn_dataset!$U$2:$U$1501,"Missing Data") -> 0
A13: % Rows Missing Data | B13: =B12/B11 -> 0
A16: Churn Rate by Plan
A17: Plan | B17: Customers | C17: Churned | D17: Churn Rate
A18: Basic | B18: =COUNTIF(customer_churn_dataset!$B$2:$B$1501,A18) -> 671 | C18: =COUNTIFS(customer_churn_dataset!$B$2:$B$1501,A18,customer_churn_dataset!$O$2:$O$1501,1) -> 137 | D18: =C18/B18 -> 0.20417288
A19: Standard | B19: =COUNTIF(customer_churn_dataset!$B$2:$B$1501,A19) -> 518 | C19: =COUNTIFS(customer_churn_dataset!$B$2:$B$1501,A19,customer_churn_dataset!$O$2:$O$1501,1) -> 86 | D19: =C19/B19 -> 0.16602317
A20: Premium | B20: =COUNTIF(customer_churn_dataset!$B$2:$B$1501,A20) -> 311 | C20: =COUNTIFS(customer_churn_dataset!$B$2:$B$1501,A20,customer_churn_dataset!$O$2:$O$1501,1) -> 61 | D20: =C20/B20 -> 0.19614148
A22: Churn Rate by Contract Type
A23: Contract Type | B23: Customers | C23: Churned | D23: Churn Rate
A24: Month-to-month | B24: =COUNTIF(customer_churn_dataset!$C$2:$C$1501,A24) -> 828 | C24: =COUNTIFS(customer_churn_dataset!$C$2:$C$1501,A24,customer_churn_dataset!$O$2:$O$1501,1) -> 233 | D24: =C24/B24 -> 0.28140097
A25: One year | B25: =COUNTIF(customer_churn_dataset!$C$2:$C$1501,A25) -> 462 | C25: =COUNTIFS(customer_churn_dataset!$C$2:$C$1501,A25,customer_churn_dataset!$O$2:$O$1501,1) -> 37 | D25: =C25/B25 -> 0.08008658
A26: Two year | B26: =COUNTIF(customer_churn_dataset!$C$2:$C$1501,A26) -> 210 | C26: =COUNTIFS(customer_churn_dataset!$C$2:$C$1501,A26,customer_churn_dataset!$O$2:$O$1501,1) -> 14 | D26: =C26/B26 -> 0.066666667
A28: Churn Rate by Tenure
A29: Tenure Bucket | B29: Customers | C29: Churned | D29: Churn Rate
A30: 0-6mo | B30: =COUNTIF(customer_churn_dataset!$S$2:$S$1501,A30) -> 359 | C30: =COUNTIFS(customer_churn_dataset!$S$2:$S$1501,A30,customer_churn_dataset!$O$2:$O$1501,1) -> 83 | D30: =C30/B30 -> 0.23119777
A31: 6-12mo | B31: =COUNTIF(customer_churn_dataset!$S$2:$S$1501,A31) -> 278 | C31: =COUNTIFS(customer_churn_dataset!$S$2:$S$1501,A31,customer_churn_dataset!$O$2:$O$1501,1) -> 69 | D31: =C31/B31 -> 0.24820144
A32: 12-24mo | B32: =COUNTIF(customer_churn_dataset!$S$2:$S$1501,A32) -> 378 | C32: =COUNTIFS(customer_churn_dataset!$S$2:$S$1501,A32,customer_churn_dataset!$O$2:$O$1501,1) -> 64 | D32: =C32/B32 -> 0.16931217
A33: 24mo+ | B33: =COUNTIF(customer_churn_dataset!$S$2:$S$1501,A33) -> 485 | C33: =COUNTIFS(customer_churn_dataset!$S$2:$S$1501,A33,customer_churn_dataset!$O$2:$O$1501,1) -> 68 | D33: =C33/B33 -> 0.14020619
A35: Revenue: Churned vs Retained
A36: Segment | B36: Customers | C36: Total Revenue | D36: Avg Revenue/Customer
A37: Retained | B37: =COUNTIF(customer_churn_dataset!$O$2:$O$1501,0) -> 1216 | C37: =SUMIFS(customer_churn_dataset!$N$2:$N$1501,customer_churn_dataset!$O$2:$O$1501,0) -> 511265.37 | D37: =C37/B37 -> 420.4485
A38: Churned | B38: =COUNTIF(customer_churn_dataset!$O$2:$O$1501,1) -> 284 | C38: =SUMIFS(customer_churn_dataset!$N$2:$N$1501,customer_churn_dataset!$O$2:$O$1501,1) -> 91109.6 | D38: =C38/B38 -> 320.80845
A39: % of Total Revenue Lost to Churn
A41: Usage Patterns by Churn Status
A42: Status | B42: Avg Usage Score | C42: Avg Logins/Month | D42: Avg Features Used
A43: Retained | B43: =IFERROR(AVERAGEIFS(customer_churn_dataset!$I$2:$I$1501,customer_churn_dataset!$O$2:$O$1501,0),"N/A") -> 55.961513 | C43: =IFERROR(AVERAGEIFS(customer_churn_dataset!$J$2:$J$1501,customer_churn_dataset!$O$2:$O$1501,0),"N/A") -> 17.037007 | D43: =IFERROR(AVERAGEIFS(customer_churn_dataset!$K$2:$K$1501,customer_churn_dataset!$O$2:$O$1501,0),"N/A") -> 5.5320724
A44: Churned | B44: =IFERROR(AVERAGEIFS(customer_churn_dataset!$I$2:$I$1501,customer_churn_dataset!$O$2:$O$1501,1),"N/A") -> 47.295775 | C44: =IFERROR(AVERAGEIFS(customer_churn_dataset!$J$2:$J$1501,customer_churn_dataset!$O$2:$O$1501,1),"N/A") -> 14.158451 | D44: =IFERROR(AVERAGEIFS(customer_churn_dataset!$K$2:$K$1501,customer_churn_dataset!$O$2:$O$1501,1),"N/A") -> 4.7676056
A46: Complaints & Churn
A47: Segment | B47: Customers | C47: Churned | D47: Churn Rate
